INFO: [main.py:32 -       main() ] ToolBox started
INFO: [programdata.py:87 - get_programfiles_folder() ] Programfiles: /opt/esa/LimeTBX
WARNING: [programdata.py:89 - get_programfiles_folder() ] Programfiles directory not valid. Using current dir.
INFO: [programdata.py:87 - get_programfiles_folder() ] Programfiles: /opt/esa/LimeTBX
WARNING: [programdata.py:89 - get_programfiles_folder() ] Programfiles directory not valid. Using current dir.
INFO: [programdata.py:87 - get_programfiles_folder() ] Programfiles: /opt/esa/LimeTBX
WARNING: [programdata.py:89 - get_programfiles_folder() ] Programfiles directory not valid. Using current dir.
ERROR: [util.py:53 -        run() ] HTTPSConnectionPool(host='localhost', port=8000): Max retries exceeded with url: /list.txt (Caused by NewConnectionError('<urllib3.connection.HTTPSConnection object at 0x7f330c701f70>: Failed to establish a new connection: [Errno 111] Conexión rehusada'))
Traceback (most recent call last):
  File "/home/javgat/Repositorios/lime_tbx/.venv/lib/python3.8/site-packages/urllib3/connection.py", line 174, in _new_conn
    conn = connection.create_connection(
  File "/home/javgat/Repositorios/lime_tbx/.venv/lib/python3.8/site-packages/urllib3/util/connection.py", line 95, in create_connection
    raise err
  File "/home/javgat/Repositorios/lime_tbx/.venv/lib/python3.8/site-packages/urllib3/util/connection.py", line 85, in create_connection
    sock.connect(sa)
ConnectionRefusedError: [Errno 111] Conexión rehusada

During handling of the above exception, another exception occurred:

Traceback (most recent call last):
  File "/home/javgat/Repositorios/lime_tbx/.venv/lib/python3.8/site-packages/urllib3/connectionpool.py", line 703, in urlopen
    httplib_response = self._make_request(
  File "/home/javgat/Repositorios/lime_tbx/.venv/lib/python3.8/site-packages/urllib3/connectionpool.py", line 386, in _make_request
    self._validate_conn(conn)
  File "/home/javgat/Repositorios/lime_tbx/.venv/lib/python3.8/site-packages/urllib3/connectionpool.py", line 1042, in _validate_conn
    conn.connect()
  File "/home/javgat/Repositorios/lime_tbx/.venv/lib/python3.8/site-packages/urllib3/connection.py", line 358, in connect
    self.sock = conn = self._new_conn()
  File "/home/javgat/Repositorios/lime_tbx/.venv/lib/python3.8/site-packages/urllib3/connection.py", line 186, in _new_conn
    raise NewConnectionError(
urllib3.exceptions.NewConnectionError: <urllib3.connection.HTTPSConnection object at 0x7f330c701f70>: Failed to establish a new connection: [Errno 111] Conexión rehusada

During handling of the above exception, another exception occurred:

Traceback (most recent call last):
  File "/home/javgat/Repositorios/lime_tbx/.venv/lib/python3.8/site-packages/requests/adapters.py", line 489, in send
    resp = conn.urlopen(
  File "/home/javgat/Repositorios/lime_tbx/.venv/lib/python3.8/site-packages/urllib3/connectionpool.py", line 787, in urlopen
    retries = retries.increment(
  File "/home/javgat/Repositorios/lime_tbx/.venv/lib/python3.8/site-packages/urllib3/util/retry.py", line 592, in increment
    raise MaxRetryError(_pool, url, error or ResponseError(cause))
urllib3.exceptions.MaxRetryError: HTTPSConnectionPool(host='localhost', port=8000): Max retries exceeded with url: /list.txt (Caused by NewConnectionError('<urllib3.connection.HTTPSConnection object at 0x7f330c701f70>: Failed to establish a new connection: [Errno 111] Conexión rehusada'))

During handling of the above exception, another exception occurred:

Traceback (most recent call last):
  File "/home/javgat/Repositorios/lime_tbx/lime_tbx/gui/util.py", line 45, in run
    res = self.callback(*self.args, self.stopper)
  File "/home/javgat/Repositorios/lime_tbx/lime_tbx/gui/coefficients.py", line 83, in _callback_download
    if updater.check_for_updates():
  File "/home/javgat/Repositorios/lime_tbx/lime_tbx/coefficients/update/update.py", line 47, in check_for_updates
    version_files = requests.get(urlpath).text.split()
  File "/home/javgat/Repositorios/lime_tbx/.venv/lib/python3.8/site-packages/requests/api.py", line 73, in get
    return request("get", url, params=params, **kwargs)
  File "/home/javgat/Repositorios/lime_tbx/.venv/lib/python3.8/site-packages/requests/api.py", line 59, in request
    return session.request(method=method, url=url, **kwargs)
  File "/home/javgat/Repositorios/lime_tbx/.venv/lib/python3.8/site-packages/requests/sessions.py", line 587, in request
    resp = self.send(prep, **send_kwargs)
  File "/home/javgat/Repositorios/lime_tbx/.venv/lib/python3.8/site-packages/requests/sessions.py", line 701, in send
    r = adapter.send(request, **kwargs)
  File "/home/javgat/Repositorios/lime_tbx/.venv/lib/python3.8/site-packages/requests/adapters.py", line 565, in send
    raise ConnectionError(e, request=request)
requests.exceptions.ConnectionError: HTTPSConnectionPool(host='localhost', port=8000): Max retries exceeded with url: /list.txt (Caused by NewConnectionError('<urllib3.connection.HTTPSConnection object at 0x7f330c701f70>: Failed to establish a new connection: [Errno 111] Conexión rehusada'))
ERROR: [coefficients.py:163 - download_error() ] HTTPSConnectionPool(host='localhost', port=8000): Max retries exceeded with url: /list.txt (Caused by NewConnectionError('<urllib3.connection.HTTPSConnection object at 0x7f330c701f70>: Failed to establish a new connection: [Errno 111] Conexión rehusada'))
INFO: [main.py:32 -       main() ] ToolBox started
INFO: [programdata.py:87 - get_programfiles_folder() ] Programfiles: /opt/esa/LimeTBX
WARNING: [programdata.py:89 - get_programfiles_folder() ] Programfiles directory not valid. Using current dir.
INFO: [programdata.py:87 - get_programfiles_folder() ] Programfiles: /opt/esa/LimeTBX
WARNING: [programdata.py:89 - get_programfiles_folder() ] Programfiles directory not valid. Using current dir.
INFO: [programdata.py:87 - get_programfiles_folder() ] Programfiles: /opt/esa/LimeTBX
WARNING: [programdata.py:89 - get_programfiles_folder() ] Programfiles directory not valid. Using current dir.
ERROR: [util.py:53 -        run() ] HTTPSConnectionPool(host='localhost', port=8000): Max retries exceeded with url: /list.txt (Caused by SSLError(SSLError(1, '[SSL: WRONG_VERSION_NUMBER] wrong version number (_ssl.c:1131)')))
Traceback (most recent call last):
  File "/home/javgat/Repositorios/lime_tbx/.venv/lib/python3.8/site-packages/urllib3/connectionpool.py", line 703, in urlopen
    httplib_response = self._make_request(
  File "/home/javgat/Repositorios/lime_tbx/.venv/lib/python3.8/site-packages/urllib3/connectionpool.py", line 386, in _make_request
    self._validate_conn(conn)
  File "/home/javgat/Repositorios/lime_tbx/.venv/lib/python3.8/site-packages/urllib3/connectionpool.py", line 1042, in _validate_conn
    conn.connect()
  File "/home/javgat/Repositorios/lime_tbx/.venv/lib/python3.8/site-packages/urllib3/connection.py", line 414, in connect
    self.sock = ssl_wrap_socket(
  File "/home/javgat/Repositorios/lime_tbx/.venv/lib/python3.8/site-packages/urllib3/util/ssl_.py", line 449, in ssl_wrap_socket
    ssl_sock = _ssl_wrap_socket_impl(
  File "/home/javgat/Repositorios/lime_tbx/.venv/lib/python3.8/site-packages/urllib3/util/ssl_.py", line 493, in _ssl_wrap_socket_impl
    return ssl_context.wrap_socket(sock, server_hostname=server_hostname)
  File "/usr/lib/python3.8/ssl.py", line 500, in wrap_socket
    return self.sslsocket_class._create(
  File "/usr/lib/python3.8/ssl.py", line 1040, in _create
    self.do_handshake()
  File "/usr/lib/python3.8/ssl.py", line 1309, in do_handshake
    self._sslobj.do_handshake()
ssl.SSLError: [SSL: WRONG_VERSION_NUMBER] wrong version number (_ssl.c:1131)

During handling of the above exception, another exception occurred:

Traceback (most recent call last):
  File "/home/javgat/Repositorios/lime_tbx/.venv/lib/python3.8/site-packages/requests/adapters.py", line 489, in send
    resp = conn.urlopen(
  File "/home/javgat/Repositorios/lime_tbx/.venv/lib/python3.8/site-packages/urllib3/connectionpool.py", line 787, in urlopen
    retries = retries.increment(
  File "/home/javgat/Repositorios/lime_tbx/.venv/lib/python3.8/site-packages/urllib3/util/retry.py", line 592, in increment
    raise MaxRetryError(_pool, url, error or ResponseError(cause))
urllib3.exceptions.MaxRetryError: HTTPSConnectionPool(host='localhost', port=8000): Max retries exceeded with url: /list.txt (Caused by SSLError(SSLError(1, '[SSL: WRONG_VERSION_NUMBER] wrong version number (_ssl.c:1131)')))

During handling of the above exception, another exception occurred:

Traceback (most recent call last):
  File "/home/javgat/Repositorios/lime_tbx/lime_tbx/gui/util.py", line 45, in run
    res = self.callback(*self.args, self.stopper)
  File "/home/javgat/Repositorios/lime_tbx/lime_tbx/gui/coefficients.py", line 83, in _callback_download
    if updater.check_for_updates():
  File "/home/javgat/Repositorios/lime_tbx/lime_tbx/coefficients/update/update.py", line 47, in check_for_updates
    version_files = requests.get(urlpath).text.split()
  File "/home/javgat/Repositorios/lime_tbx/.venv/lib/python3.8/site-packages/requests/api.py", line 73, in get
    return request("get", url, params=params, **kwargs)
  File "/home/javgat/Repositorios/lime_tbx/.venv/lib/python3.8/site-packages/requests/api.py", line 59, in request
    return session.request(method=method, url=url, **kwargs)
  File "/home/javgat/Repositorios/lime_tbx/.venv/lib/python3.8/site-packages/requests/sessions.py", line 587, in request
    resp = self.send(prep, **send_kwargs)
  File "/home/javgat/Repositorios/lime_tbx/.venv/lib/python3.8/site-packages/requests/sessions.py", line 701, in send
    r = adapter.send(request, **kwargs)
  File "/home/javgat/Repositorios/lime_tbx/.venv/lib/python3.8/site-packages/requests/adapters.py", line 563, in send
    raise SSLError(e, request=request)
requests.exceptions.SSLError: HTTPSConnectionPool(host='localhost', port=8000): Max retries exceeded with url: /list.txt (Caused by SSLError(SSLError(1, '[SSL: WRONG_VERSION_NUMBER] wrong version number (_ssl.c:1131)')))
ERROR: [coefficients.py:163 - download_error() ] HTTPSConnectionPool(host='localhost', port=8000): Max retries exceeded with url: /list.txt (Caused by SSLError(SSLError(1, '[SSL: WRONG_VERSION_NUMBER] wrong version number (_ssl.c:1131)')))
INFO: [main.py:32 -       main() ] ToolBox started
INFO: [programdata.py:87 - get_programfiles_folder() ] Programfiles: /opt/esa/LimeTBX
WARNING: [programdata.py:89 - get_programfiles_folder() ] Programfiles directory not valid. Using current dir.
INFO: [programdata.py:87 - get_programfiles_folder() ] Programfiles: /opt/esa/LimeTBX
WARNING: [programdata.py:89 - get_programfiles_folder() ] Programfiles directory not valid. Using current dir.
INFO: [programdata.py:87 - get_programfiles_folder() ] Programfiles: /opt/esa/LimeTBX
WARNING: [programdata.py:89 - get_programfiles_folder() ] Programfiles directory not valid. Using current dir.
ERROR: [util.py:53 -        run() ] HTTPSConnectionPool(host='localhost', port=8000): Max retries exceeded with url: /list.txt (Caused by SSLError(SSLError(1, '[SSL: WRONG_VERSION_NUMBER] wrong version number (_ssl.c:1131)')))
Traceback (most recent call last):
  File "/home/javgat/Repositorios/lime_tbx/.venv/lib/python3.8/site-packages/urllib3/connectionpool.py", line 703, in urlopen
    httplib_response = self._make_request(
  File "/home/javgat/Repositorios/lime_tbx/.venv/lib/python3.8/site-packages/urllib3/connectionpool.py", line 386, in _make_request
    self._validate_conn(conn)
  File "/home/javgat/Repositorios/lime_tbx/.venv/lib/python3.8/site-packages/urllib3/connectionpool.py", line 1042, in _validate_conn
    conn.connect()
  File "/home/javgat/Repositorios/lime_tbx/.venv/lib/python3.8/site-packages/urllib3/connection.py", line 414, in connect
    self.sock = ssl_wrap_socket(
  File "/home/javgat/Repositorios/lime_tbx/.venv/lib/python3.8/site-packages/urllib3/util/ssl_.py", line 449, in ssl_wrap_socket
    ssl_sock = _ssl_wrap_socket_impl(
  File "/home/javgat/Repositorios/lime_tbx/.venv/lib/python3.8/site-packages/urllib3/util/ssl_.py", line 493, in _ssl_wrap_socket_impl
    return ssl_context.wrap_socket(sock, server_hostname=server_hostname)
  File "/usr/lib/python3.8/ssl.py", line 500, in wrap_socket
    return self.sslsocket_class._create(
  File "/usr/lib/python3.8/ssl.py", line 1040, in _create
    self.do_handshake()
  File "/usr/lib/python3.8/ssl.py", line 1309, in do_handshake
    self._sslobj.do_handshake()
ssl.SSLError: [SSL: WRONG_VERSION_NUMBER] wrong version number (_ssl.c:1131)

During handling of the above exception, another exception occurred:

Traceback (most recent call last):
  File "/home/javgat/Repositorios/lime_tbx/.venv/lib/python3.8/site-packages/requests/adapters.py", line 489, in send
    resp = conn.urlopen(
  File "/home/javgat/Repositorios/lime_tbx/.venv/lib/python3.8/site-packages/urllib3/connectionpool.py", line 787, in urlopen
    retries = retries.increment(
  File "/home/javgat/Repositorios/lime_tbx/.venv/lib/python3.8/site-packages/urllib3/util/retry.py", line 592, in increment
    raise MaxRetryError(_pool, url, error or ResponseError(cause))
urllib3.exceptions.MaxRetryError: HTTPSConnectionPool(host='localhost', port=8000): Max retries exceeded with url: /list.txt (Caused by SSLError(SSLError(1, '[SSL: WRONG_VERSION_NUMBER] wrong version number (_ssl.c:1131)')))

During handling of the above exception, another exception occurred:

Traceback (most recent call last):
  File "/home/javgat/Repositorios/lime_tbx/lime_tbx/gui/util.py", line 45, in run
    res = self.callback(*self.args, self.stopper)
  File "/home/javgat/Repositorios/lime_tbx/lime_tbx/gui/coefficients.py", line 83, in _callback_download
    if updater.check_for_updates():
  File "/home/javgat/Repositorios/lime_tbx/lime_tbx/coefficients/update/update.py", line 48, in check_for_updates
    version_files = requests.get(urlpath).text.split()
  File "/home/javgat/Repositorios/lime_tbx/.venv/lib/python3.8/site-packages/requests/api.py", line 73, in get
    return request("get", url, params=params, **kwargs)
  File "/home/javgat/Repositorios/lime_tbx/.venv/lib/python3.8/site-packages/requests/api.py", line 59, in request
    return session.request(method=method, url=url, **kwargs)
  File "/home/javgat/Repositorios/lime_tbx/.venv/lib/python3.8/site-packages/requests/sessions.py", line 587, in request
    resp = self.send(prep, **send_kwargs)
  File "/home/javgat/Repositorios/lime_tbx/.venv/lib/python3.8/site-packages/requests/sessions.py", line 701, in send
    r = adapter.send(request, **kwargs)
  File "/home/javgat/Repositorios/lime_tbx/.venv/lib/python3.8/site-packages/requests/adapters.py", line 563, in send
    raise SSLError(e, request=request)
requests.exceptions.SSLError: HTTPSConnectionPool(host='localhost', port=8000): Max retries exceeded with url: /list.txt (Caused by SSLError(SSLError(1, '[SSL: WRONG_VERSION_NUMBER] wrong version number (_ssl.c:1131)')))
ERROR: [coefficients.py:163 - download_error() ] HTTPSConnectionPool(host='localhost', port=8000): Max retries exceeded with url: /list.txt (Caused by SSLError(SSLError(1, '[SSL: WRONG_VERSION_NUMBER] wrong version number (_ssl.c:1131)')))
INFO: [main.py:32 -       main() ] ToolBox started
INFO: [programdata.py:87 - get_programfiles_folder() ] Programfiles: /opt/esa/LimeTBX
WARNING: [programdata.py:89 - get_programfiles_folder() ] Programfiles directory not valid. Using current dir.
INFO: [programdata.py:87 - get_programfiles_folder() ] Programfiles: /opt/esa/LimeTBX
WARNING: [programdata.py:89 - get_programfiles_folder() ] Programfiles directory not valid. Using current dir.
INFO: [programdata.py:87 - get_programfiles_folder() ] Programfiles: /opt/esa/LimeTBX
WARNING: [programdata.py:89 - get_programfiles_folder() ] Programfiles directory not valid. Using current dir.
INFO: [programdata.py:87 - get_programfiles_folder() ] Programfiles: /opt/esa/LimeTBX
WARNING: [programdata.py:89 - get_programfiles_folder() ] Programfiles directory not valid. Using current dir.
ERROR: [util.py:53 -        run() ] 'bool' object is not iterable
Traceback (most recent call last):
  File "/home/javgat/Repositorios/lime_tbx/lime_tbx/gui/util.py", line 51, in run
    self.finished.emit(list(res))
TypeError: 'bool' object is not iterable
ERROR: [coefficients.py:163 - download_error() ] 'bool' object is not iterable
INFO: [main.py:32 -       main() ] ToolBox started
INFO: [programdata.py:87 - get_programfiles_folder() ] Programfiles: /opt/esa/LimeTBX
WARNING: [programdata.py:89 - get_programfiles_folder() ] Programfiles directory not valid. Using current dir.
INFO: [programdata.py:87 - get_programfiles_folder() ] Programfiles: /opt/esa/LimeTBX
WARNING: [programdata.py:89 - get_programfiles_folder() ] Programfiles directory not valid. Using current dir.
INFO: [programdata.py:87 - get_programfiles_folder() ] Programfiles: /opt/esa/LimeTBX
WARNING: [programdata.py:89 - get_programfiles_folder() ] Programfiles directory not valid. Using current dir.
INFO: [programdata.py:87 - get_programfiles_folder() ] Programfiles: /opt/esa/LimeTBX
WARNING: [programdata.py:89 - get_programfiles_folder() ] Programfiles directory not valid. Using current dir.
